<?xml version="1.0" encoding="utf-8"?>
<!-- This URDF was automatically created by SolidWorks to URDF Exporter! Originally created by Stephen Brawner (brawner@gmail.com) 
     Commit Version: 1.5.1-0-g916b5db  Build Version: 1.5.7152.31018
     For more information, please see http://wiki.ros.org/sw_urdf_exporter -->
<robot
  name="ikfk">
  <link
    name="l1">
    <visual>
      <origin
        xyz="0 0 0"
        rpy="0 0 0" />
      <geometry>
        <mesh
          filename="package://ikfk/meshes/l1.STL" />
      </geometry>
      <material
        name="">
        <color
          rgba="0.792156862745098 0.819607843137255 0.933333333333333 1" />
      </material>
    </visual>
    <collision>
      <origin
        xyz="0 0 0"
        rpy="0 0 0" />
      <geometry>
        <mesh
          filename="package://ikfk/meshes/l1.STL" />
      </geometry>
    </collision>
  </link>
  <link
    name="l2">
    <inertial>
      <origin
        xyz="0 0 0"
        rpy="0 0 0" />
      <mass
        value="0.347127023267661" />
      <inertia
        ixx="0.0010631192190086"
        ixy="6.15593279798226E-06"
        ixz="0.000161124006894344"
        iyy="0.000931431429298643"
        iyz="-1.83909348020823E-05"
        izz="0.00072003854037119" />
    </inertial>
    <visual>
      <origin
        xyz="0 0 0"
        rpy="0 0 0" />
      <geometry>
        <mesh
          filename="package://ikfk/meshes/l2.STL" />
      </geometry>
      <material
        name="">
        <color
          rgba="0.792156862745098 0.819607843137255 0.933333333333333 1" />
      </material>
    </visual>
    <collision>
      <origin
        xyz="0 0 0"
        rpy="0 0 0" />
      <geometry>
        <mesh
          filename="package://ikfk/meshes/l2.STL" />
      </geometry>
    </collision>
  </link>
  <joint
    name="j2"
    type="revolute">
    <origin
      xyz="0.0 0.0 0.076805"
      rpy="3.1416 0 -1.5708" />
    <parent
      link="l1" />
    <child
      link="l2" />
    <axis
      xyz="0 0 1" />
    <limit
      lower="-3.14"
      upper="3.14"
      effort="0"
      velocity="0" />
  </joint>
  <link
    name="l3">
    <inertial>
      <origin
        xyz="1.37195912323917E-06 0.0646794629105503 -0.0485196106286587"
        rpy="0 0 0" />
      <mass
        value="0.583453144895476" />
      <inertia
        ixx="0.00328336018185868"
        ixy="9.68500972067701E-09"
        ixz="-5.28773122862605E-09"
        iyy="0.000909190266083572"
        iyz="-2.81677088089766E-05"
        izz="0.00389999556317457" />
    </inertial>
    <visual>
      <origin
        xyz="0 0 0"
        rpy="0 0 0" />
      <geometry>
        <mesh
          filename="package://ikfk/meshes/l3.STL" />
      </geometry>
      <material
        name="">
        <color
          rgba="0.792156862745098 0.819607843137255 0.933333333333333 1" />
      </material>
    </visual>
    <collision>
      <origin
        xyz="0 0 0"
        rpy="0 0 0" />
      <geometry>
        <mesh
          filename="package://ikfk/meshes/l3.STL" />
      </geometry>
    </collision>
  </link>
  <joint
    name="j3"
    type="revolute">
    <origin
      xyz="0.054992 0 -0.099"
      rpy="-1.5708 0 1.5708" />
    <parent
      link="l2" />
    <child
      link="l3" />
    <axis
      xyz="0 0 1" />
    <limit
      lower="-3.14"
      upper="3.14"
      effort="0"
      velocity="0" />
  </joint>
  <link
    name="l4">
    <inertial>
      <origin
        xyz="0.000123532810478142 0.059730075861426 -0.0490246520414468"
        rpy="0 0 0" />
      <mass
        value="0.569532543154534" />
      <inertia
        ixx="0.00361842190269119"
        ixy="6.05083989004087E-06"
        ixz="2.09838730204066E-07"
        iyy="0.000902446541780071"
        iyz="-3.15103807275629E-05"
        izz="0.00423020835537969" />
    </inertial>
    <visual>
      <origin
        xyz="0 0 0"
        rpy="0 0 0" />
      <geometry>
        <mesh
          filename="package://ikfk/meshes/l4.STL" />
      </geometry>
      <material
        name="">
        <color
          rgba="0.792156862745098 0.819607843137255 0.933333333333333 1" />
      </material>
    </visual>
    <collision>
      <origin
        xyz="0 0 0"
        rpy="0 0 0" />
      <geometry>
        <mesh
          filename="package://ikfk/meshes/l4.STL" />
      </geometry>
    </collision>
  </link>
  <joint
    name="j4"
    type="revolute">
    <origin
      xyz="0 0.16 0"
      rpy="3.1416 0 -3.1416" />
    <parent
      link="l3" />
    <child
      link="l4" />
    <axis
      xyz="0 0 1" />
    <limit
      lower="-3.14"
      upper="3.14"
      effort="0"
      velocity="0" />
  </joint>
  <link
    name="l5">
    <inertial>
      <origin
        xyz="-0.0455868193439153 3.28775120669866E-08 -0.0232451647106656"
        rpy="0 0 0" />
      <mass
        value="0.439375654076011" />
      <inertia
        ixx="0.00164430181444721"
        ixy="-4.83318110242674E-10"
        ixz="-8.15513652380298E-05"
        iyy="0.00125393176666983"
        iyz="3.71418147083124E-10"
        izz="0.000702329493050405" />
    </inertial>
    <visual>
      <origin
        xyz="0 0 0"
        rpy="0 0 0" />
      <geometry>
        <mesh
          filename="package://ikfk/meshes/l5.STL" />
      </geometry>
      <material
        name="">
        <color
          rgba="0.792156862745098 0.819607843137255 0.933333333333333 1" />
      </material>
    </visual>
    <collision>
      <origin
        xyz="0 0 0"
        rpy="0 0 0" />
      <geometry>
        <mesh
          filename="package://ikfk/meshes/l5.STL" />
      </geometry>
    </collision>
  </link>
  <joint
    name="j5"
    type="revolute">
    <origin
      xyz="0 0.16 0"
      rpy="1.5708 1.5708 0" />
    <parent
      link="l4" />
    <child
      link="l5" />
    <axis
      xyz="1 0 0" />
    <limit
      lower="-3.14"
      upper="3.14"
      effort="0"
      velocity="0" />
  </joint>
  <link
    name="l6">
    <inertial>
      <origin
        xyz="0.00148871261288458 0.00029573531886019 -0.0628228486462078"
        rpy="0 0 0" />
      <mass
        value="0.334585426652201" />
      <inertia
        ixx="0.00106191583037582"
        ixy="-7.80849925393899E-07"
        ixz="0.000141944739515501"
        iyy="0.000890956181395683"
        iyz="-3.45067831895538E-06"
        izz="0.000695963723394054" />
    </inertial>
    <visual>
      <origin
        xyz="0 0 0"
        rpy="0 0 0" />
      <geometry>
        <mesh
          filename="package://ikfk/meshes/l6.STL" />
      </geometry>
      <material
        name="">
        <color
          rgba="0.792156862745098 0.819607843137255 0.933333333333333 1" />
      </material>
    </visual>
    <collision>
      <origin
        xyz="0 0 0"
        rpy="0 0 0" />
      <geometry>
        <mesh
          filename="package://ikfk/meshes/l6.STL" />
      </geometry>
    </collision>
  </link>
  <joint
    name="j6"
    type="revolute">
    <origin
      xyz="-0.055008 0 -0.12"
      rpy="0 0 0" />
    <parent
      link="l5" />
    <child
      link="l6" />
    <axis
      xyz="0 0 1" />
    <limit
      lower="-3.14"
      upper="3.14"
      effort="0"
      velocity="0" />
  </joint>
  <link
    name="end_link">
    <inertial>
      <origin
        xyz="0 -5.20417042793042E-18 0.0169609937058888"
        rpy="0 0 0" />
      <mass
        value="0.155292459158679" />
      <inertia
        ixx="0.000181315026178621"
        ixy="-3.08799285804403E-21"
        ixz="-1.0675067942841E-20"
        iyy="0.000181315026178621"
        iyz="-1.51710728690118E-20"
        izz="0.000334796454737857" />
    </inertial>
    <visual>
      <origin
        xyz="0 0 0"
        rpy="0 0 0" />
      <geometry>
        <mesh
          filename="package://ikfk/meshes/end_link.STL" />
      </geometry>
      <material
        name="">
        <color
          rgba="0.792156862745098 0.819607843137255 0.933333333333333 1" />
      </material>
    </visual>
    <collision>
      <origin
        xyz="0 0 0"
        rpy="0 0 0" />
      <geometry>
        <mesh
          filename="package://ikfk/meshes/end_link.STL" />
      </geometry>
    </collision>
  </link>
  <joint
    name="end_joint"
    type="revolute">
    <origin
      xyz="0.055 0 -0.099"
      rpy="0 1.5708 0" />
    <parent
      link="l6" />
    <child
      link="end_link" />
    <axis
      xyz="0 0 1" />
    <limit
      lower="-3.14"
      upper="3.14"
      effort="0"
      velocity="0" />
  </joint>
</robot>